2025-05-05 23:55:48,159 - api.menu_bridge_core.views - INFO - Menu item list returned: count: 1
2025-05-05 23:55:48,209 - api.menu_bridge_core.views - ERROR - Error while retrieving item list: unsupported operand type(s) for *: 'decimal.Decimal' and 'float'
Traceback (most recent call last):
  File "/app/restora_project/api/menu_bridge_core/views.py", line 136, in get
    return Response(serializer.data, status=status.HTTP_200_OK)
                    ^^^^^^^^^^^^^^^
  File "/usr/local/lib/python3.12/site-packages/rest_framework/serializers.py", line 797, in data
    ret = super().data
          ^^^^^^^^^^^^
  File "/usr/local/lib/python3.12/site-packages/rest_framework/serializers.py", line 251, in data
    self._data = self.to_representation(self.instance)
                 ^^^^^^^^^^^^^^^^^^^^^^^^^^^^^^^^^^^^^
  File "/usr/local/lib/python3.12/site-packages/rest_framework/serializers.py", line 716, in to_representation
    self.child.to_representation(item) for item in iterable
    ^^^^^^^^^^^^^^^^^^^^^^^^^^^^^^^^^^
  File "/usr/local/lib/python3.12/site-packages/rest_framework/serializers.py", line 527, in to_representation
    attribute = field.get_attribute(instance)
                ^^^^^^^^^^^^^^^^^^^^^^^^^^^^^
  File "/usr/local/lib/python3.12/site-packages/rest_framework/fields.py", line 437, in get_attribute
    return get_attribute(instance, self.source_attrs)
           ^^^^^^^^^^^^^^^^^^^^^^^^^^^^^^^^^^^^^^^^^^
  File "/usr/local/lib/python3.12/site-packages/rest_framework/fields.py", line 109, in get_attribute
    instance = instance()
               ^^^^^^^^^^
  File "/app/restora_project/project_apps/menu/models.py", line 46, in get_discounted_price
    return self.price * (1 - self.discount_percentage / 100)
           ~~~~~~~~~~~^~~~~~~~~~~~~~~~~~~~~~~~~~~~~~~~~~~~~~
TypeError: unsupported operand type(s) for *: 'decimal.Decimal' and 'float'
2025-05-05 23:56:39,850 - api.menu_bridge_core.views - INFO - Menu item list returned: count: 1
2025-05-05 23:56:39,866 - api.menu_bridge_core.views - ERROR - Error while retrieving item list: unsupported operand type(s) for *: 'decimal.Decimal' and 'float'
Traceback (most recent call last):
  File "/app/restora_project/api/menu_bridge_core/views.py", line 136, in get
    return Response(serializer.data, status=status.HTTP_200_OK)
                    ^^^^^^^^^^^^^^^
  File "/usr/local/lib/python3.12/site-packages/rest_framework/serializers.py", line 797, in data
    ret = super().data
          ^^^^^^^^^^^^
  File "/usr/local/lib/python3.12/site-packages/rest_framework/serializers.py", line 251, in data
    self._data = self.to_representation(self.instance)
                 ^^^^^^^^^^^^^^^^^^^^^^^^^^^^^^^^^^^^^
  File "/usr/local/lib/python3.12/site-packages/rest_framework/serializers.py", line 716, in to_representation
    self.child.to_representation(item) for item in iterable
    ^^^^^^^^^^^^^^^^^^^^^^^^^^^^^^^^^^
  File "/usr/local/lib/python3.12/site-packages/rest_framework/serializers.py", line 527, in to_representation
    attribute = field.get_attribute(instance)
                ^^^^^^^^^^^^^^^^^^^^^^^^^^^^^
  File "/usr/local/lib/python3.12/site-packages/rest_framework/fields.py", line 437, in get_attribute
    return get_attribute(instance, self.source_attrs)
           ^^^^^^^^^^^^^^^^^^^^^^^^^^^^^^^^^^^^^^^^^^
  File "/usr/local/lib/python3.12/site-packages/rest_framework/fields.py", line 109, in get_attribute
    instance = instance()
               ^^^^^^^^^^
  File "/app/restora_project/project_apps/menu/models.py", line 46, in get_discounted_price
    return self.price * (1 - self.discount_percentage / 100)
           ~~~~~~~~~~~^~~~~~~~~~~~~~~~~~~~~~~~~~~~~~~~~~~~~~
TypeError: unsupported operand type(s) for *: 'decimal.Decimal' and 'float'
2025-05-05 23:56:43,076 - api.menu_bridge_core.views - INFO - Menu item list returned: count: 1
2025-05-05 23:56:43,085 - api.menu_bridge_core.views - ERROR - Error while retrieving item list: unsupported operand type(s) for *: 'decimal.Decimal' and 'float'
Traceback (most recent call last):
  File "/app/restora_project/api/menu_bridge_core/views.py", line 136, in get
    return Response(serializer.data, status=status.HTTP_200_OK)
                    ^^^^^^^^^^^^^^^
  File "/usr/local/lib/python3.12/site-packages/rest_framework/serializers.py", line 797, in data
    ret = super().data
          ^^^^^^^^^^^^
  File "/usr/local/lib/python3.12/site-packages/rest_framework/serializers.py", line 251, in data
    self._data = self.to_representation(self.instance)
                 ^^^^^^^^^^^^^^^^^^^^^^^^^^^^^^^^^^^^^
  File "/usr/local/lib/python3.12/site-packages/rest_framework/serializers.py", line 716, in to_representation
    self.child.to_representation(item) for item in iterable
    ^^^^^^^^^^^^^^^^^^^^^^^^^^^^^^^^^^
  File "/usr/local/lib/python3.12/site-packages/rest_framework/serializers.py", line 527, in to_representation
    attribute = field.get_attribute(instance)
                ^^^^^^^^^^^^^^^^^^^^^^^^^^^^^
  File "/usr/local/lib/python3.12/site-packages/rest_framework/fields.py", line 437, in get_attribute
    return get_attribute(instance, self.source_attrs)
           ^^^^^^^^^^^^^^^^^^^^^^^^^^^^^^^^^^^^^^^^^^
  File "/usr/local/lib/python3.12/site-packages/rest_framework/fields.py", line 109, in get_attribute
    instance = instance()
               ^^^^^^^^^^
  File "/app/restora_project/project_apps/menu/models.py", line 46, in get_discounted_price
    return self.price * (1 - self.discount_percentage / 100)
           ~~~~~~~~~~~^~~~~~~~~~~~~~~~~~~~~~~~~~~~~~~~~~~~~~
TypeError: unsupported operand type(s) for *: 'decimal.Decimal' and 'float'
2025-05-05 23:57:17,715 - api.menu_bridge_core.views - INFO - Category list returned: count: 1
2025-05-05 23:57:30,613 - api.menu_bridge_core.views - INFO - Category details found: ID 1
2025-05-06 00:05:58,786 - api.menu_bridge_core.views - INFO - Category list returned: count: 1
2025-05-06 00:06:13,999 - api.menu_bridge_core.views - ERROR - Category ID not provided
2025-05-06 00:06:35,687 - api.menu_bridge_core.views - INFO - Menu item list returned: count: 1
2025-05-06 00:06:35,726 - api.menu_bridge_core.views - ERROR - Error while retrieving item list: unsupported operand type(s) for *: 'decimal.Decimal' and 'float'
Traceback (most recent call last):
  File "/app/restora_project/api/menu_bridge_core/views.py", line 136, in get
    return Response(serializer.data, status=status.HTTP_200_OK)
                    ^^^^^^^^^^^^^^^
  File "/usr/local/lib/python3.12/site-packages/rest_framework/serializers.py", line 797, in data
    ret = super().data
          ^^^^^^^^^^^^
  File "/usr/local/lib/python3.12/site-packages/rest_framework/serializers.py", line 251, in data
    self._data = self.to_representation(self.instance)
                 ^^^^^^^^^^^^^^^^^^^^^^^^^^^^^^^^^^^^^
  File "/usr/local/lib/python3.12/site-packages/rest_framework/serializers.py", line 716, in to_representation
    self.child.to_representation(item) for item in iterable
    ^^^^^^^^^^^^^^^^^^^^^^^^^^^^^^^^^^
  File "/usr/local/lib/python3.12/site-packages/rest_framework/serializers.py", line 527, in to_representation
    attribute = field.get_attribute(instance)
                ^^^^^^^^^^^^^^^^^^^^^^^^^^^^^
  File "/usr/local/lib/python3.12/site-packages/rest_framework/fields.py", line 437, in get_attribute
    return get_attribute(instance, self.source_attrs)
           ^^^^^^^^^^^^^^^^^^^^^^^^^^^^^^^^^^^^^^^^^^
  File "/usr/local/lib/python3.12/site-packages/rest_framework/fields.py", line 109, in get_attribute
    instance = instance()
               ^^^^^^^^^^
  File "/app/restora_project/project_apps/menu/models.py", line 46, in get_discounted_price
    return self.price * (1 - self.discount_percentage / 100)
           ~~~~~~~~~~~^~~~~~~~~~~~~~~~~~~~~~~~~~~~~~~~~~~~~~
TypeError: unsupported operand type(s) for *: 'decimal.Decimal' and 'float'
2025-05-06 00:11:46,738 - api.menu_bridge_core.views - INFO - Menu item list returned: count: 1
2025-05-06 00:11:46,747 - api.menu_bridge_core.views - ERROR - Error while retrieving item list: The field 'image_url' was declared on serializer MenuItemSerializer, but has not been included in the 'fields' option.
Traceback (most recent call last):
  File "/app/restora_project/api/menu_bridge_core/views.py", line 136, in get
    return Response(serializer.data, status=status.HTTP_200_OK)
                    ^^^^^^^^^^^^^^^
  File "/usr/local/lib/python3.12/site-packages/rest_framework/serializers.py", line 797, in data
    ret = super().data
          ^^^^^^^^^^^^
  File "/usr/local/lib/python3.12/site-packages/rest_framework/serializers.py", line 251, in data
    self._data = self.to_representation(self.instance)
                 ^^^^^^^^^^^^^^^^^^^^^^^^^^^^^^^^^^^^^
  File "/usr/local/lib/python3.12/site-packages/rest_framework/serializers.py", line 716, in to_representation
    self.child.to_representation(item) for item in iterable
    ^^^^^^^^^^^^^^^^^^^^^^^^^^^^^^^^^^
  File "/usr/local/lib/python3.12/site-packages/rest_framework/serializers.py", line 525, in to_representation
    for field in fields:
                 ^^^^^^
  File "/usr/local/lib/python3.12/site-packages/rest_framework/serializers.py", line 386, in _readable_fields
    for field in self.fields.values():
                 ^^^^^^^^^^^
  File "/usr/local/lib/python3.12/site-packages/django/utils/functional.py", line 47, in __get__
    res = instance.__dict__[self.name] = self.func(instance)
                                         ^^^^^^^^^^^^^^^^^^^
  File "/usr/local/lib/python3.12/site-packages/rest_framework/serializers.py", line 374, in fields
    for key, value in self.get_fields().items():
                      ^^^^^^^^^^^^^^^^^
  File "/usr/local/lib/python3.12/site-packages/rest_framework/serializers.py", line 1081, in get_fields
    field_names = self.get_field_names(declared_fields, info)
                  ^^^^^^^^^^^^^^^^^^^^^^^^^^^^^^^^^^^^^^^^^^^
  File "/usr/local/lib/python3.12/site-packages/rest_framework/serializers.py", line 1177, in get_field_names
    assert field_name in fields, (
           ^^^^^^^^^^^^^^^^^^^^
AssertionError: The field 'image_url' was declared on serializer MenuItemSerializer, but has not been included in the 'fields' option.
2025-05-06 20:12:49,004 - api.menu_bridge_core.views - ERROR - Unauthorized menu item modification: Guest, ID: 1
2025-05-06 20:13:23,713 - api.menu_bridge_core.views - ERROR - Menu item ID not provided
2025-05-24 23:40:26,162 - api.menu_bridge_core.views - ERROR - Error while retrieving category list: relation "menu_category" does not exist
LINE 1: SELECT COUNT(*) AS "__count" FROM "menu_category" WHERE NOT ...
                                          ^
Traceback (most recent call last):
  File "/usr/local/lib/python3.12/site-packages/django/db/backends/utils.py", line 105, in _execute
    return self.cursor.execute(sql, params)
           ^^^^^^^^^^^^^^^^^^^^^^^^^^^^^^^^
psycopg2.errors.UndefinedTable: relation "menu_category" does not exist
LINE 1: SELECT COUNT(*) AS "__count" FROM "menu_category" WHERE NOT ...
                                          ^


The above exception was the direct cause of the following exception:

Traceback (most recent call last):
  File "/app/restora_project/api/menu_bridge_core/views.py", line 34, in get
    logger.info(f"Category list returned: count: {categories.count()}")
                                                  ^^^^^^^^^^^^^^^^^^
  File "/usr/local/lib/python3.12/site-packages/django/db/models/query.py", line 620, in count
    return self.query.get_count(using=self.db)
           ^^^^^^^^^^^^^^^^^^^^^^^^^^^^^^^^^^^
  File "/usr/local/lib/python3.12/site-packages/django/db/models/sql/query.py", line 630, in get_count
    return obj.get_aggregation(using, {"__count": Count("*")})["__count"]
           ^^^^^^^^^^^^^^^^^^^^^^^^^^^^^^^^^^^^^^^^^^^^^^^^^^^
  File "/usr/local/lib/python3.12/site-packages/django/db/models/sql/query.py", line 616, in get_aggregation
    result = compiler.execute_sql(SINGLE)
             ^^^^^^^^^^^^^^^^^^^^^^^^^^^^
  File "/usr/local/lib/python3.12/site-packages/django/db/models/sql/compiler.py", line 1574, in execute_sql
    cursor.execute(sql, params)
  File "/usr/local/lib/python3.12/site-packages/django/db/backends/utils.py", line 122, in execute
    return super().execute(sql, params)
           ^^^^^^^^^^^^^^^^^^^^^^^^^^^^
  File "/usr/local/lib/python3.12/site-packages/django/db/backends/utils.py", line 79, in execute
    return self._execute_with_wrappers(
           ^^^^^^^^^^^^^^^^^^^^^^^^^^^^
  File "/usr/local/lib/python3.12/site-packages/django/db/backends/utils.py", line 92, in _execute_with_wrappers
    return executor(sql, params, many, context)
           ^^^^^^^^^^^^^^^^^^^^^^^^^^^^^^^^^^^^
  File "/usr/local/lib/python3.12/site-packages/django/db/backends/utils.py", line 100, in _execute
    with self.db.wrap_database_errors:
         ^^^^^^^^^^^^^^^^^^^^^^^^^^^^
  File "/usr/local/lib/python3.12/site-packages/django/db/utils.py", line 91, in __exit__
    raise dj_exc_value.with_traceback(traceback) from exc_value
  File "/usr/local/lib/python3.12/site-packages/django/db/backends/utils.py", line 105, in _execute
    return self.cursor.execute(sql, params)
           ^^^^^^^^^^^^^^^^^^^^^^^^^^^^^^^^
django.db.utils.ProgrammingError: relation "menu_category" does not exist
LINE 1: SELECT COUNT(*) AS "__count" FROM "menu_category" WHERE NOT ...
                                          ^

2025-05-25 00:06:28,273 - api.menu_bridge_core.views - ERROR - Error while retrieving item list: relation "menu_menuitem" does not exist
LINE 1: SELECT COUNT(*) AS "__count" FROM "menu_menuitem" WHERE NOT ...
                                          ^
Traceback (most recent call last):
  File "/usr/local/lib/python3.12/site-packages/django/db/backends/utils.py", line 105, in _execute
    return self.cursor.execute(sql, params)
           ^^^^^^^^^^^^^^^^^^^^^^^^^^^^^^^^
psycopg2.errors.UndefinedTable: relation "menu_menuitem" does not exist
LINE 1: SELECT COUNT(*) AS "__count" FROM "menu_menuitem" WHERE NOT ...
                                          ^


The above exception was the direct cause of the following exception:

Traceback (most recent call last):
  File "/app/restora_project/api/menu_bridge_core/views.py", line 135, in get
    logger.info(f"Menu item list returned: count: {items.count()}")
                                                   ^^^^^^^^^^^^^
  File "/usr/local/lib/python3.12/site-packages/django/db/models/query.py", line 620, in count
    return self.query.get_count(using=self.db)
           ^^^^^^^^^^^^^^^^^^^^^^^^^^^^^^^^^^^
  File "/usr/local/lib/python3.12/site-packages/django/db/models/sql/query.py", line 630, in get_count
    return obj.get_aggregation(using, {"__count": Count("*")})["__count"]
           ^^^^^^^^^^^^^^^^^^^^^^^^^^^^^^^^^^^^^^^^^^^^^^^^^^^
  File "/usr/local/lib/python3.12/site-packages/django/db/models/sql/query.py", line 616, in get_aggregation
    result = compiler.execute_sql(SINGLE)
             ^^^^^^^^^^^^^^^^^^^^^^^^^^^^
  File "/usr/local/lib/python3.12/site-packages/django/db/models/sql/compiler.py", line 1574, in execute_sql
    cursor.execute(sql, params)
  File "/usr/local/lib/python3.12/site-packages/django/db/backends/utils.py", line 122, in execute
    return super().execute(sql, params)
           ^^^^^^^^^^^^^^^^^^^^^^^^^^^^
  File "/usr/local/lib/python3.12/site-packages/django/db/backends/utils.py", line 79, in execute
    return self._execute_with_wrappers(
           ^^^^^^^^^^^^^^^^^^^^^^^^^^^^
  File "/usr/local/lib/python3.12/site-packages/django/db/backends/utils.py", line 92, in _execute_with_wrappers
    return executor(sql, params, many, context)
           ^^^^^^^^^^^^^^^^^^^^^^^^^^^^^^^^^^^^
  File "/usr/local/lib/python3.12/site-packages/django/db/backends/utils.py", line 100, in _execute
    with self.db.wrap_database_errors:
         ^^^^^^^^^^^^^^^^^^^^^^^^^^^^
  File "/usr/local/lib/python3.12/site-packages/django/db/utils.py", line 91, in __exit__
    raise dj_exc_value.with_traceback(traceback) from exc_value
  File "/usr/local/lib/python3.12/site-packages/django/db/backends/utils.py", line 105, in _execute
    return self.cursor.execute(sql, params)
           ^^^^^^^^^^^^^^^^^^^^^^^^^^^^^^^^
django.db.utils.ProgrammingError: relation "menu_menuitem" does not exist
LINE 1: SELECT COUNT(*) AS "__count" FROM "menu_menuitem" WHERE NOT ...
                                          ^

2025-05-25 00:08:50,463 - api.menu_bridge_core.views - ERROR - Error while retrieving item list: relation "menu_menuitem" does not exist
LINE 1: ...able", "menu_menuitem"."discount_percentage" FROM "menu_menu...
                                                             ^
Traceback (most recent call last):
  File "/usr/local/lib/python3.12/site-packages/django/db/backends/utils.py", line 105, in _execute
    return self.cursor.execute(sql, params)
           ^^^^^^^^^^^^^^^^^^^^^^^^^^^^^^^^
psycopg2.errors.UndefinedTable: relation "menu_menuitem" does not exist
LINE 1: ...able", "menu_menuitem"."discount_percentage" FROM "menu_menu...
                                                             ^


The above exception was the direct cause of the following exception:

Traceback (most recent call last):
  File "/app/restora_project/api/menu_bridge_core/views.py", line 125, in get
    item = MenuItem.objects.filter(id=item_id, is_deleted=False).first()
           ^^^^^^^^^^^^^^^^^^^^^^^^^^^^^^^^^^^^^^^^^^^^^^^^^^^^^^^^^^^^^
  File "/usr/local/lib/python3.12/site-packages/django/db/models/query.py", line 1097, in first
    for obj in queryset[:1]:
               ~~~~~~~~^^^^
  File "/usr/local/lib/python3.12/site-packages/django/db/models/query.py", line 400, in __iter__
    self._fetch_all()
  File "/usr/local/lib/python3.12/site-packages/django/db/models/query.py", line 1928, in _fetch_all
    self._result_cache = list(self._iterable_class(self))
                         ^^^^^^^^^^^^^^^^^^^^^^^^^^^^^^^^
  File "/usr/local/lib/python3.12/site-packages/django/db/models/query.py", line 91, in __iter__
    results = compiler.execute_sql(
              ^^^^^^^^^^^^^^^^^^^^^
  File "/usr/local/lib/python3.12/site-packages/django/db/models/sql/compiler.py", line 1574, in execute_sql
    cursor.execute(sql, params)
  File "/usr/local/lib/python3.12/site-packages/django/db/backends/utils.py", line 122, in execute
    return super().execute(sql, params)
           ^^^^^^^^^^^^^^^^^^^^^^^^^^^^
  File "/usr/local/lib/python3.12/site-packages/django/db/backends/utils.py", line 79, in execute
    return self._execute_with_wrappers(
           ^^^^^^^^^^^^^^^^^^^^^^^^^^^^
  File "/usr/local/lib/python3.12/site-packages/django/db/backends/utils.py", line 92, in _execute_with_wrappers
    return executor(sql, params, many, context)
           ^^^^^^^^^^^^^^^^^^^^^^^^^^^^^^^^^^^^
  File "/usr/local/lib/python3.12/site-packages/django/db/backends/utils.py", line 100, in _execute
    with self.db.wrap_database_errors:
         ^^^^^^^^^^^^^^^^^^^^^^^^^^^^
  File "/usr/local/lib/python3.12/site-packages/django/db/utils.py", line 91, in __exit__
    raise dj_exc_value.with_traceback(traceback) from exc_value
  File "/usr/local/lib/python3.12/site-packages/django/db/backends/utils.py", line 105, in _execute
    return self.cursor.execute(sql, params)
           ^^^^^^^^^^^^^^^^^^^^^^^^^^^^^^^^
django.db.utils.ProgrammingError: relation "menu_menuitem" does not exist
LINE 1: ...able", "menu_menuitem"."discount_percentage" FROM "menu_menu...
                                                             ^

2025-05-25 00:08:58,009 - api.menu_bridge_core.views - ERROR - Error while retrieving item list: relation "menu_menuitem" does not exist
LINE 1: ...able", "menu_menuitem"."discount_percentage" FROM "menu_menu...
                                                             ^
Traceback (most recent call last):
  File "/usr/local/lib/python3.12/site-packages/django/db/backends/utils.py", line 105, in _execute
    return self.cursor.execute(sql, params)
           ^^^^^^^^^^^^^^^^^^^^^^^^^^^^^^^^
psycopg2.errors.UndefinedTable: relation "menu_menuitem" does not exist
LINE 1: ...able", "menu_menuitem"."discount_percentage" FROM "menu_menu...
                                                             ^


The above exception was the direct cause of the following exception:

Traceback (most recent call last):
  File "/app/restora_project/api/menu_bridge_core/views.py", line 125, in get
    item = MenuItem.objects.filter(id=item_id, is_deleted=False).first()
           ^^^^^^^^^^^^^^^^^^^^^^^^^^^^^^^^^^^^^^^^^^^^^^^^^^^^^^^^^^^^^
  File "/usr/local/lib/python3.12/site-packages/django/db/models/query.py", line 1097, in first
    for obj in queryset[:1]:
               ~~~~~~~~^^^^
  File "/usr/local/lib/python3.12/site-packages/django/db/models/query.py", line 400, in __iter__
    self._fetch_all()
  File "/usr/local/lib/python3.12/site-packages/django/db/models/query.py", line 1928, in _fetch_all
    self._result_cache = list(self._iterable_class(self))
                         ^^^^^^^^^^^^^^^^^^^^^^^^^^^^^^^^
  File "/usr/local/lib/python3.12/site-packages/django/db/models/query.py", line 91, in __iter__
    results = compiler.execute_sql(
              ^^^^^^^^^^^^^^^^^^^^^
  File "/usr/local/lib/python3.12/site-packages/django/db/models/sql/compiler.py", line 1574, in execute_sql
    cursor.execute(sql, params)
  File "/usr/local/lib/python3.12/site-packages/django/db/backends/utils.py", line 122, in execute
    return super().execute(sql, params)
           ^^^^^^^^^^^^^^^^^^^^^^^^^^^^
  File "/usr/local/lib/python3.12/site-packages/django/db/backends/utils.py", line 79, in execute
    return self._execute_with_wrappers(
           ^^^^^^^^^^^^^^^^^^^^^^^^^^^^
  File "/usr/local/lib/python3.12/site-packages/django/db/backends/utils.py", line 92, in _execute_with_wrappers
    return executor(sql, params, many, context)
           ^^^^^^^^^^^^^^^^^^^^^^^^^^^^^^^^^^^^
  File "/usr/local/lib/python3.12/site-packages/django/db/backends/utils.py", line 100, in _execute
    with self.db.wrap_database_errors:
         ^^^^^^^^^^^^^^^^^^^^^^^^^^^^
  File "/usr/local/lib/python3.12/site-packages/django/db/utils.py", line 91, in __exit__
    raise dj_exc_value.with_traceback(traceback) from exc_value
  File "/usr/local/lib/python3.12/site-packages/django/db/backends/utils.py", line 105, in _execute
    return self.cursor.execute(sql, params)
           ^^^^^^^^^^^^^^^^^^^^^^^^^^^^^^^^
django.db.utils.ProgrammingError: relation "menu_menuitem" does not exist
LINE 1: ...able", "menu_menuitem"."discount_percentage" FROM "menu_menu...
                                                             ^

